Workbook

Sheet 1_Matriz_confusion_vs_costo
A1: Matriz de confusión vs. matriz de costos
A2: La matriz de confusión cuenta decisiones correctas e incorrectas. La matriz de costos asigna una consecuencia económica a cada tipo de decisión.
A4: Parámetro | B4: Valor
A5: Umbral utilizado | B5: ='2_Costos_fijos'!B13 -> 0.01
A6: Costo TP | B6: ='2_Costos_fijos'!B6 -> 5
A7: Costo FP | B7: ='2_Costos_fijos'!B7 -> 5
A8: Costo FN | B8: ='2_Costos_fijos'!B9 -> 500
A10: 1. Matriz de confusión: cantidades | F10: 2. Matriz de costos: costo por observación | K10: 3. Contribución al costo total
A11: Real \ Predicción | B11: Alerta = 1 | C11: No alerta = 0 | D11: Total real | F11: Real \ Decisión | G11: Alerta = 1 | H11: No alerta = 0 | I11: Lectura | K11: Real \ Decisión | L11: Alerta = 1 | M11: No alerta = 0 | N11: Total real
A12: Fraude = 1 | B12: ='2_Costos_fijos'!F5 -> 1 | C12: ='2_Costos_fijos'!F7 -> 0 | D12: =SUM(B12:C12) -> 1 | F12: Fraude = 1 | G12: ='2_Costos_fijos'!B6 -> 5 | H12: ='2_Costos_fijos'!B9 -> 500 | I12: CTP frente a CFN | K12: Fraude = 1 | L12: =B12*G12 -> 5 | M12: =C12*H12 -> 0 | N12: =SUM(L12:M12) -> 5
A13: Legítima = 0 | B13: ='2_Costos_fijos'!F6 -> 13 | C13: ='2_Costos_fijos'!F8 -> 86 | D13: =SUM(B13:C13) -> 99 | F13: Legítima = 0 | G13: ='2_Costos_fijos'!B7 -> 5 | H13: ='2_Costos_fijos'!B10 -> 0 | I13: CFP frente a CTN | K13: Legítima = 0 | L13: =B13*G13 -> 65 | M13: =C13*H13 -> 0 | N13: =SUM(L13:M13) -> 65
A14: Total predicho | B14: =SUM(B12:B13) -> 14 | C14: =SUM(C12:C13) -> 86 | D14: =SUM(B12:C13) -> 100 | F14: Unidad | G14: $ por caso | H14: $ por caso | K14: Total decisión | L14: =SUM(L12:L13) -> 70 | M14: =SUM(M12:M13) -> 0 | N14: =SUM(L12:M13) -> 70
A16: Celda | B16: Nombre | C16: Qué significa | D16: ¿Es error? | F16: Métricas derivadas de cantidades | K16: Métricas económicas
A17: Fraude–Alerta | B17: TP | C17: Se detecta un fraude | D17: No | F17: Accuracy | G17: =IFERROR((B12+C13)/D14,0) -> 0.87 | K17: Costo total | L17: =N14 -> 70
A18: Fraude–No alerta | B18: FN | C18: El fraude pasa sin ser detectado | D18: Sí | F18: Recall fraude | G18: =IFERROR(B12/D12,0) -> 1 | K18: Costo promedio por operación | L18: =IFERROR(N14/D14,0) -> 0.7
A19: Legítima–Alerta | B19: FP | C19: Se investiga o bloquea una operación legítima | D19: Sí | F19: Precision | G19: =IFERROR(B12/B14,0) -> 0.071428571 | K19: Costo sin modelo | L19: ='2_Costos_fijos'!F9 -> 500
A20: Legítima–No alerta | B20: TN | C20: La operación legítima pasa normalmente | D20: No | F20: Tasa de falsos positivos | G20: =IFERROR(B13/D13,0) -> 0.13131313 | K20: Ahorro vs. sin modelo | L20: =IFERROR(1-L17/L19,0) -> 0.86
A23: Lectura conceptual
A24: Pregunta | B24: Respuesta | D24: Ejemplo para discutir en clase: Dos modelos pueden tener la misma cantidad total de errores, pero costos muy distintos. Un modelo con 10 falsos positivos y 1 falso negativo puede ser preferible a otro con 1 falso positivo y 10 falsos negativos cuando el fraude omitido cuesta mucho más que una revisión innecesaria. En la hoja 2, además, el costo del falso negativo depende del monto: ya no existe una sola matriz de costos común a todas las observaciones.
A25: ¿Qué informa la matriz de confusión? | B25: Cuántos TP, FP, FN y TN produjo el clasificador.
A26: ¿Qué agrega la matriz de costos? | B26: Cuánto vale económicamente cada tipo de resultado.
A27: ¿Por qué accuracy puede engañar? | B27: Porque trata como equivalentes errores con consecuencias económicas muy distintas.
A28: ¿Qué optimizamos en cost-sensitive learning? | B28: El costo o riesgo esperado, no necesariamente la cantidad de errores.
A31: Costo total = TP·CTP + FP·CFP + FN·CFN + TN·CTN

Sheet 2_Costos_fijos
A1: Optimización del umbral con costos fijos por clase
A2: Todas las observaciones comparten la misma matriz de costos. Se comparan el umbral teórico de Bayes y el umbral empírico que minimiza el costo en la muestra.
A4: Supuestos editables | E4: Resultados con el umbral elegido | J4: Umbral | K4: Costo total ($) | L4: TP | M4: FP | N4: FN | O4: TN | P4: Accuracy
A5: Costo administrativo Ca ($) | B5: 5 | C5: Input | E5: TP | F5: =COUNTIFS($B$17:$B$116,">="&$B$13,$C$17:$C$116,1) -> 1 | J5: 0 | K5: =L5*$B$6+M5*$B$7+N5*$B$9+O5*$B$10 -> 500 | L5: =COUNTIFS($B$17:$B$116,">="&J5,$C$17:$C$116,1) -> 1 | M5: =COUNTIFS($B$17:$B$116,">="&J5,$C$17:$C$116,0) -> 99 | N5: =COUNTIFS($B$17:$B$116,"<"&J5,$C$17:$C$116,1) -> 0 | O5: =COUNTIFS($B$17:$B$116,"<"&J5,$C$17:$C$116,0) -> 0 | P5: =IFERROR((L5+O5)/SUM(L5:O5),0) -> 0.01
A6: Costo verdadero positivo CTP ($) | B6: =B5 -> 5 | C6: Se incurre por revisar/contactar | E6: FP | F6: =COUNTIFS($B$17:$B$116,">="&$B$13,$C$17:$C$116,0) -> 13 | J6: =J5+$B$14 -> 0.005 | K6: =L6*$B$6+M6*$B$7+N6*$B$9+O6*$B$10 -> 130 | L6: =COUNTIFS($B$17:$B$116,">="&J6,$C$17:$C$116,1) -> 1 | M6: =COUNTIFS($B$17:$B$116,">="&J6,$C$17:$C$116,0) -> 25 | N6: =COUNTIFS($B$17:$B$116,"<"&J6,$C$17:$C$116,1) -> 0 | O6: =COUNTIFS($B$17:$B$116,"<"&J6,$C$17:$C$116,0) -> 74 | P6: =IFERROR((L6+O6)/SUM(L6:O6),0) -> 0.75
A7: Costo falso positivo CFP ($) | B7: =B5 -> 5 | C7: Se incurre por revisar una operación legítima | E7: FN | F7: =COUNTIFS($B$17:$B$116,"<"&$B$13,$C$17:$C$116,1) -> 0 | J7: =J6+$B$14 -> 0.01 | K7: =L7*$B$6+M7*$B$7+N7*$B$9+O7*$B$10 -> 70 | L7: =COUNTIFS($B$17:$B$116,">="&J7,$C$17:$C$116,1) -> 1 | M7: =COUNTIFS($B$17:$B$116,">="&J7,$C$17:$C$116,0) -> 13 | N7: =COUNTIFS($B$17:$B$116,"<"&J7,$C$17:$C$116,1) -> 0 | O7: =COUNTIFS($B$17:$B$116,"<"&J7,$C$17:$C$116,0) -> 86 | P7: =IFERROR((L7+O7)/SUM(L7:O7),0) -> 0.87
A8: Multiplicador del falso negativo | B8: 100 | C8: Correa/Bahnsen usa 100 × Ca en la matriz fija | E8: TN | F8: =COUNTIFS($B$17:$B$116,"<"&$B$13,$C$17:$C$116,0) -> 86 | J8: =J7+$B$14 -> 0.015 | K8: =L8*$B$6+M8*$B$7+N8*$B$9+O8*$B$10 -> 530 | L8: =COUNTIFS($B$17:$B$116,">="&J8,$C$17:$C$116,1) -> 0 | M8: =COUNTIFS($B$17:$B$116,">="&J8,$C$17:$C$116,0) -> 6 | N8: =COUNTIFS($B$17:$B$116,"<"&J8,$C$17:$C$116,1) -> 1 | O8: =COUNTIFS($B$17:$B$116,"<"&J8,$C$17:$C$116,0) -> 93 | P8: =IFERROR((L8+O8)/SUM(L8:O8),0) -> 0.93
A9: Costo falso negativo CFN ($) | B9: =B5*B8 -> 500 | C9: Pérdida fija para cualquier fraude omitido | E9: Costo sin modelo (todo legítimo) | F9: =COUNTIF($C$17:$C$116,1)*$B$9+COUNTIF($C$17:$C$116,0)*$B$10 -> 500 | J9: =J8+$B$14 -> 0.02 | K9: =L9*$B$6+M9*$B$7+N9*$B$9+O9*$B$10 -> 520 | L9: =COUNTIFS($B$17:$B$116,">="&J9,$C$17:$C$116,1) -> 0 | M9: =COUNTIFS($B$17:$B$116,">="&J9,$C$17:$C$116,0) -> 4 | N9: =COUNTIFS($B$17:$B$116,"<"&J9,$C$17:$C$116,1) -> 1 | O9: =COUNTIFS($B$17:$B$116,"<"&J9,$C$17:$C$116,0) -> 95 | P9: =IFERROR((L9+O9)/SUM(L9:O9),0) -> 0.95
A10: Costo verdadero negativo CTN ($) | B10: 0 | C10: Sin costo | E10: Costo con umbral elegido | F10: =F5*$B$6+F6*$B$7+F7*$B$9+F8*$B$10 -> 70 | J10: =J9+$B$14 -> 0.025 | K10: =L10*$B$6+M10*$B$7+N10*$B$9+O10*$B$10 -> 515 | L10: =COUNTIFS($B$17:$B$116,">="&J10,$C$17:$C$116,1) -> 0 | M10: =COUNTIFS($B$17:$B$116,">="&J10,$C$17:$C$116,0) -> 3 | N10: =COUNTIFS($B$17:$B$116,"<"&J10,$C$17:$C$116,1) -> 1 | O10: =COUNTIFS($B$17:$B$116,"<"&J10,$C$17:$C$116,0) -> 96 | P10: =IFERROR((L10+O10)/SUM(L10:O10),0) -> 0.96
A11: Umbral teórico de Bayes | B11: =IFERROR((B7-B10)/((B7-B10)+(B9-B6)),0.5) -> 0.01 | C11: (CFP-CTN)/[(CFP-CTN)+(CFN-CTP)] | E11: Ahorro vs. sin modelo | F11: =IFERROR(1-F10/F9,0) -> 0.86 | J11: =J10+$B$14 -> 0.03 | K11: =L11*$B$6+M11*$B$7+N11*$B$9+O11*$B$10 -> 510 | L11: =COUNTIFS($B$17:$B$116,">="&J11,$C$17:$C$116,1) -> 0 | M11: =COUNTIFS($B$17:$B$116,">="&J11,$C$17:$C$116,0) -> 2 | N11: =COUNTIFS($B$17:$B$116,"<"&J11,$C$17:$C$116,1) -> 1 | O11: =COUNTIFS($B$17:$B$116,"<"&J11,$C$17:$C$116,0) -> 97 | P11: =IFERROR((L11+O11)/SUM(L11:O11),0) -> 0.97
A12: Mejor umbral empírico | B12: =INDEX($J$5:$J$45,MATCH(MIN($K$5:$K$45),$K$5:$K$45,0)) -> 0.01 | C12: Mínimo costo observado en la grilla | E12: Accuracy | F12: =IFERROR((F5+F8)/SUM(F5:F8),0) -> 0.87 | J12: =J11+$B$14 -> 0.035 | K12: =L12*$B$6+M12*$B$7+N12*$B$9+O12*$B$10 -> 510 | L12: =COUNTIFS($B$17:$B$116,">="&J12,$C$17:$C$116,1) -> 0 | M12: =COUNTIFS($B$17:$B$116,">="&J12,$C$17:$C$116,0) -> 2 | N12: =COUNTIFS($B$17:$B$116,"<"&J12,$C$17:$C$116,1) -> 1 | O12: =COUNTIFS($B$17:$B$116,"<"&J12,$C$17:$C$116,0) -> 97 | P12: =IFERROR((L12+O12)/SUM(L12:O12),0) -> 0.97
A13: Umbral usado en la tabla | B13: 0.01 | C13: Editable: probá 50%, el teórico y el empírico | E13: Recall | F13: =IFERROR(F5/(F5+F7),0) -> 1 | J13: =J12+$B$14 -> 0.04 | K13: =L13*$B$6+M13*$B$7+N13*$B$9+O13*$B$10 -> 505 | L13: =COUNTIFS($B$17:$B$116,">="&J13,$C$17:$C$116,1) -> 0 | M13: =COUNTIFS($B$17:$B$116,">="&J13,$C$17:$C$116,0) -> 1 | N13: =COUNTIFS($B$17:$B$116,"<"&J13,$C$17:$C$116,1) -> 1 | O13: =COUNTIFS($B$17:$B$116,"<"&J13,$C$17:$C$116,0) -> 98 | P13: =IFERROR((L13+O13)/SUM(L13:O13),0) -> 0.98
A14: Paso de la grilla | B14: 0.005 | C14: 0,5 puntos porcentuales | E14: Precision | F14: =IFERROR(F5/(F5+F6),0) -> 0.071428571 | J14: =J13+$B$14 -> 0.045 | K14: =L14*$B$6+M14*$B$7+N14*$B$9+O14*$B$10 -> 505 | L14: =COUNTIFS($B$17:$B$116,">="&J14,$C$17:$C$116,1) -> 0 | M14: =COUNTIFS($B$17:$B$116,">="&J14,$C$17:$C$116,0) -> 1 | N14: =COUNTIFS($B$17:$B$116,"<"&J14,$C$17:$C$116,1) -> 1 | O14: =COUNTIFS($B$17:$B$116,"<"&J14,$C$17:$C$116,0) -> 98 | P14: =IFERROR((L14+O14)/SUM(L14:O14),0) -> 0.98
J15: =J14+$B$14 -> 0.05 | K15: =L15*$B$6+M15*$B$7+N15*$B$9+O15*$B$10 -> 505 | L15: =COUNTIFS($B$17:$B$116,">="&J15,$C$17:$C$116,1) -> 0 | M15: =COUNTIFS($B$17:$B$116,">="&J15,$C$17:$C$116,0) -> 1 | N15: =COUNTIFS($B$17:$B$116,"<"&J15,$C$17:$C$116,1) -> 1 | O15: =COUNTIFS($B$17:$B$116,"<"&J15,$C$17:$C$116,0) -> 98 | P15: =IFERROR((L15+O15)/SUM(L15:O15),0) -> 0.98
A16: ID | B16: Prob. fraude estimada | C16: Fraude real (1/0) | D16: Predicción | E16: Resultado | F16: Costo realizado ($) | G16: Comentario | J16: =J15+$B$14 -> 0.055 | K16: =L16*$B$6+M16*$B$7+N16*$B$9+O16*$B$10 -> 505 | L16: =COUNTIFS($B$17:$B$116,">="&J16,$C$17:$C$116,1) -> 0 | M16: =COUNTIFS($B$17:$B$116,">="&J16,$C$17:$C$116,0) -> 1 | N16: =COUNTIFS($B$17:$B$116,"<"&J16,$C$17:$C$116,1) -> 1 | O16: =COUNTIFS($B$17:$B$116,"<"&J16,$C$17:$C$116,0) -> 98 | P16: =IFERROR((L16+O16)/SUM(L16:O16),0) -> 0.98
A17: T001 | B17: 0.0001 | C17: 0 | D17: =--(B17>=$B$13) -> 0 | E17: =IF(C17=1,IF(D17=1,"TP","FN"),IF(D17=1,"FP","TN")) -> TN | F17: =IF(C17=1,IF(D17=1,$B$6,$B$9),IF(D17=1,$B$7,$B$10)) -> 0 | G17: =IF(E17="FN","Fraude no detectado",IF(E17="FP","Alerta innecesaria","")) | J17: =J16+$B$14 -> 0.06 | K17: =L17*$B$6+M17*$B$7+N17*$B$9+O17*$B$10 -> 505 | L17: =COUNTIFS($B$17:$B$116,">="&J17,$C$17:$C$116,1) -> 0 | M17: =COUNTIFS($B$17:$B$116,">="&J17,$C$17:$C$116,0) -> 1 | N17: =COUNTIFS($B$17:$B$116,"<"&J17,$C$17:$C$116,1) -> 1 | O17: =COUNTIFS($B$17:$B$116,"<"&J17,$C$17:$C$116,0) -> 98 | P17: =IFERROR((L17+O17)/SUM(L17:O17),0) -> 0.98
A18: T002 | B18: 0.000209 | C18: 0 | D18: =--(B18>=$B$13) -> 0 | E18: =IF(C18=1,IF(D18=1,"TP","FN"),IF(D18=1,"FP","TN")) -> TN | F18: =IF(C18=1,IF(D18=1,$B$6,$B$9),IF(D18=1,$B$7,$B$10)) -> 0 | G18: =IF(E18="FN","Fraude no detectado",IF(E18="FP","Alerta innecesaria","")) | J18: =J17+$B$14 -> 0.065 | K18: =L18*$B$6+M18*$B$7+N18*$B$9+O18*$B$10 -> 500 | L18: =COUNTIFS($B$17:$B$116,">="&J18,$C$17:$C$116,1) -> 0 | M18: =COUNTIFS($B$17:$B$116,">="&J18,$C$17:$C$116,0) -> 0 | N18: =COUNTIFS($B$17:$B$116,"<"&J18,$C$17:$C$116,1) -> 1 | O18: =COUNTIFS($B$17:$B$116,"<"&J18,$C$17:$C$116,0) -> 99 | P18: =IFERROR((L18+O18)/SUM(L18:O18),0) -> 0.99
A19: T003 | B19: 0.0036 | C19: 0 | D19: =--(B19>=$B$13) -> 0 | E19: =IF(C19=1,IF(D19=1,"TP","FN"),IF(D19=1,"FP","TN")) -> TN | F19: =IF(C19=1,IF(D19=1,$B$6,$B$9),IF(D19=1,$B$7,$B$10)) -> 0 | G19: =IF(E19="FN","Fraude no detectado",IF(E19="FP","Alerta innecesaria","")) | J19: =J18+$B$14 -> 0.07 | K19: =L19*$B$6+M19*$B$7+N19*$B$9+O19*$B$10 -> 500 | L19: =COUNTIFS($B$17:$B$116,">="&J19,$C$17:$C$116,1) -> 0 | M19: =COUNTIFS($B$17:$B$116,">="&J19,$C$17:$C$116,0) -> 0 | N19: =COUNTIFS($B$17:$B$116,"<"&J19,$C$17:$C$116,1) -> 1 | O19: =COUNTIFS($B$17:$B$116,"<"&J19,$C$17:$C$116,0) -> 99 | P19: =IFERROR((L19+O19)/SUM(L19:O19),0) -> 0.99
A20: T004 | B20: 0.0001 | C20: 0 | D20: =--(B20>=$B$13) -> 0 | E20: =IF(C20=1,IF(D20=1,"TP","FN"),IF(D20=1,"FP","TN")) -> TN | F20: =IF(C20=1,IF(D20=1,$B$6,$B$9),IF(D20=1,$B$7,$B$10)) -> 0 | G20: =IF(E20="FN","Fraude no detectado",IF(E20="FP","Alerta innecesaria","")) | J20: =J19+$B$14 -> 0.075 | K20: =L20*$B$6+M20*$B$7+N20*$B$9+O20*$B$10 -> 500 | L20: =COUNTIFS($B$17:$B$116,">="&J20,$C$17:$C$116,1) -> 0 | M20: =COUNTIFS($B$17:$B$116,">="&J20,$C$17:$C$116,0) -> 0 | N20: =COUNTIFS($B$17:$B$116,"<"&J20,$C$17:$C$116,1) -> 1 | O20: =COUNTIFS($B$17:$B$116,"<"&J20,$C$17:$C$116,0) -> 99 | P20: =IFERROR((L20+O20)/SUM(L20:O20),0) -> 0.99
A21: T005 | B21: 0.000502 | C21: 0 | D21: =--(B21>=$B$13) -> 0 | E21: =IF(C21=1,IF(D21=1,"TP","FN"),IF(D21=1,"FP","TN")) -> TN | F21: =IF(C21=1,IF(D21=1,$B$6,$B$9),IF(D21=1,$B$7,$B$10)) -> 0 | G21: =IF(E21="FN","Fraude no detectado",IF(E21="FP","Alerta innecesaria","")) | J21: =J20+$B$14 -> 0.08 | K21: =L21*$B$6+M21*$B$7+N21*$B$9+O21*$B$10 -> 500 | L21: =COUNTIFS($B$17:$B$116,">="&J21,$C$17:$C$116,1) -> 0 | M21: =COUNTIFS($B$17:$B$116,">="&J21,$C$17:$C$116,0) -> 0 | N21: =COUNTIFS($B$17:$B$116,"<"&J21,$C$17:$C$116,1) -> 1 | O21: =COUNTIFS($B$17:$B$116,"<"&J21,$C$17:$C$116,0) -> 99 | P21: =IFERROR((L21+O21)/SUM(L21:O21),0) -> 0.99
A22: T006 | B22: 0.007099 | C22: 0 | D22: =--(B22>=$B$13) -> 0 | E22: =IF(C22=1,IF(D22=1,"TP","FN"),IF(D22=1,"FP","TN")) -> TN | F22: =IF(C22=1,IF(D22=1,$B$6,$B$9),IF(D22=1,$B$7,$B$10)) -> 0 | G22: =IF(E22="FN","Fraude no detectado",IF(E22="FP","Alerta innecesaria","")) | J22: =J21+$B$14 -> 0.085 | K22: =L22*$B$6+M22*$B$7+N22*$B$9+O22*$B$10 -> 500 | L22: =COUNTIFS($B$17:$B$116,">="&J22,$C$17:$C$116,1) -> 0 | M22: =COUNTIFS($B$17:$B$116,">="&J22,$C$17:$C$116,0) -> 0 | N22: =COUNTIFS($B$17:$B$116,"<"&J22,$C$17:$C$116,1) -> 1 | O22: =COUNTIFS($B$17:$B$116,"<"&J22,$C$17:$C$116,0) -> 99 | P22: =IFERROR((L22+O22)/SUM(L22:O22),0) -> 0.99
A23: T007 | B23: 0.000108 | C23: 0 | D23: =--(B23>=$B$13) -> 0 | E23: =IF(C23=1,IF(D23=1,"TP","FN"),IF(D23=1,"FP","TN")) -> TN | F23: =IF(C23=1,IF(D23=1,$B$6,$B$9),IF(D23=1,$B$7,$B$10)) -> 0 | G23: =IF(E23="FN","Fraude no detectado",IF(E23="FP","Alerta innecesaria","")) | J23: =J22+$B$14 -> 0.09 | K23: =L23*$B$6+M23*$B$7+N23*$B$9+O23*$B$10 -> 500 | L23: =COUNTIFS($B$17:$B$116,">="&J23,$C$17:$C$116,1) -> 0 | M23: =COUNTIFS($B$17:$B$116,">="&J23,$C$17:$C$116,0) -> 0 | N23: =COUNTIFS($B$17:$B$116,"<"&J23,$C$17:$C$116,1) -> 1 | O23: =COUNTIFS($B$17:$B$116,"<"&J23,$C$17:$C$116,0) -> 99 | P23: =IFERROR((L23+O23)/SUM(L23:O23),0) -> 0.99
A24: T008 | B24: 0.02 | C24: 0 | D24: =--(B24>=$B$13) -> 1 | E24: =IF(C24=1,IF(D24=1,"TP","FN"),IF(D24=1,"FP","TN")) -> FP | F24: =IF(C24=1,IF(D24=1,$B$6,$B$9),IF(D24=1,$B$7,$B$10)) -> 5 | G24: =IF(E24="FN","Fraude no detectado",IF(E24="FP","Alerta innecesaria","")) -> Alerta innecesaria | J24: =J23+$B$14 -> 0.095 | K24: =L24*$B$6+M24*$B$7+N24*$B$9+O24*$B$10 -> 500 | L24: =COUNTIFS($B$17:$B$116,">="&J24,$C$17:$C$116,1) -> 0 | M24: =COUNTIFS($B$17:$B$116,">="&J24,$C$17:$C$116,0) -> 0 | N24: =COUNTIFS($B$17:$B$116,"<"&J24,$C$17:$C$116,1) -> 1 | O24: =COUNTIFS($B$17:$B$116,"<"&J24,$C$17:$C$116,0) -> 99 | P24: =IFERROR((L24+O24)/SUM(L24:O24),0) -> 0.99
A25: T009 | B25: 0.012961 | C25: 0 | D25: =--(B25>=$B$13) -> 1 | E25: =IF(C25=1,IF(D25=1,"TP","FN"),IF(D25=1,"FP","TN")) -> FP | F25: =IF(C25=1,IF(D25=1,$B$6,$B$9),IF(D25=1,$B$7,$B$10)) -> 5 | G25: =IF(E25="FN","Fraude no detectado",IF(E25="FP","Alerta innecesaria","")) -> Alerta innecesaria | J25: =J24+$B$14 -> 0.1 | K25: =L25*$B$6+M25*$B$7+N25*$B$9+O25*$B$10 -> 500 | L25: =COUNTIFS($B$17:$B$116,">="&J25,$C$17:$C$116,1) -> 0 | M25: =COUNTIFS($B$17:$B$116,">="&J25,$C$17:$C$116,0) -> 0 | N25: =COUNTIFS($B$17:$B$116,"<"&J25,$C$17:$C$116,1) -> 1 | O25: =COUNTIFS($B$17:$B$116,"<"&J25,$C$17:$C$116,0) -> 99 | P25: =IFERROR((L25+O25)/SUM(L25:O25),0) -> 0.99
A26: T010 | B26: 0.000162 | C26: 0 | D26: =--(B26>=$B$13) -> 0 | E26: =IF(C26=1,IF(D26=1,"TP","FN"),IF(D26=1,"FP","TN")) -> TN | F26: =IF(C26=1,IF(D26=1,$B$6,$B$9),IF(D26=1,$B$7,$B$10)) -> 0 | G26: =IF(E26="FN","Fraude no detectado",IF(E26="FP","Alerta innecesaria","")) | J26: =J25+$B$14 -> 0.105 | K26: =L26*$B$6+M26*$B$7+N26*$B$9+O26*$B$10 -> 500 | L26: =COUNTIFS($B$17:$B$116,">="&J26,$C$17:$C$116,1) -> 0 | M26: =COUNTIFS($B$17:$B$116,">="&J26,$C$17:$C$116,0) -> 0 | N26: =COUNTIFS($B$17:$B$116,"<"&J26,$C$17:$C$116,1) -> 1 | O26: =COUNTIFS($B$17:$B$116,"<"&J26,$C$17:$C$116,0) -> 99 | P26: =IFERROR((L26+O26)/SUM(L26:O26),0) -> 0.99
A27: T011 | B27: 0.002751 | C27: 0 | D27: =--(B27>=$B$13) -> 0 | E27: =IF(C27=1,IF(D27=1,"TP","FN"),IF(D27=1,"FP","TN")) -> TN | F27: =IF(C27=1,IF(D27=1,$B$6,$B$9),IF(D27=1,$B$7,$B$10)) -> 0 | G27: =IF(E27="FN","Fraude no detectado",IF(E27="FP","Alerta innecesaria","")) | J27: =J26+$B$14 -> 0.11 | K27: =L27*$B$6+M27*$B$7+N27*$B$9+O27*$B$10 -> 500 | L27: =COUNTIFS($B$17:$B$116,">="&J27,$C$17:$C$116,1) -> 0 | M27: =COUNTIFS($B$17:$B$116,">="&J27,$C$17:$C$116,0) -> 0 | N27: =COUNTIFS($B$17:$B$116,"<"&J27,$C$17:$C$116,1) -> 1 | O27: =COUNTIFS($B$17:$B$116,"<"&J27,$C$17:$C$116,0) -> 99 | P27: =IFERROR((L27+O27)/SUM(L27:O27),0) -> 0.99
A28: T012 | B28: 0.0001 | C28: 0 | D28: =--(B28>=$B$13) -> 0 | E28: =IF(C28=1,IF(D28=1,"TP","FN"),IF(D28=1,"FP","TN")) -> TN | F28: =IF(C28=1,IF(D28=1,$B$6,$B$9),IF(D28=1,$B$7,$B$10)) -> 0 | G28: =IF(E28="FN","Fraude no detectado",IF(E28="FP","Alerta innecesaria","")) | J28: =J27+$B$14 -> 0.115 | K28: =L28*$B$6+M28*$B$7+N28*$B$9+O28*$B$10 -> 500 | L28: =COUNTIFS($B$17:$B$116,">="&J28,$C$17:$C$116,1) -> 0 | M28: =COUNTIFS($B$17:$B$116,">="&J28,$C$17:$C$116,0) -> 0 | N28: =COUNTIFS($B$17:$B$116,"<"&J28,$C$17:$C$116,1) -> 1 | O28: =COUNTIFS($B$17:$B$116,"<"&J28,$C$17:$C$116,0) -> 99 | P28: =IFERROR((L28+O28)/SUM(L28:O28),0) -> 0.99
... A45: T029 | B45: 0.000195 | C45: 0 | D45: =--(B45>=$B$13) -> 0 | E45: =IF(C45=1,IF(D45=1,"TP","FN"),IF(D45=1,"FP","TN")) -> TN | F45: =IF(C45=1,IF(D45=1,$B$6,$B$9),IF(D45=1,$B$7,$B$10)) -> 0 | G45: =IF(E45="FN","Fraude no detectado",IF(E45="FP","Alerta innecesaria","")) | J45: =J44+$B$14 -> 0.2 | K45: =L45*$B$6+M45*$B$7+N45*$B$9+O45*$B$10 -> 500 | L45: =COUNTIFS($B$17:$B$116,">="&J45,$C$17:$C$116,1) -> 0 | M45: =COUNTIFS($B$17:$B$116,">="&J45,$C$17:$C$116,0) -> 0 | N45: =COUNTIFS($B$17:$B$116,"<"&J45,$C$17:$C$116,1) -> 1 | O45: =COUNTIFS($B$17:$B$116,"<"&J45,$C$17:$C$116,0) -> 99 | P45: =IFERROR((L45+O45)/SUM(L45:O45),0) -> 0.99
A46: T030 | B46: 0.00337 | C46: 0 | D46: =--(B46>=$B$13) -> 0 | E46: =IF(C46=1,IF(D46=1,"TP","FN"),IF(D46=1,"FP","TN")) -> TN | F46: =IF(C46=1,IF(D46=1,$B$6,$B$9),IF(D46=1,$B$7,$B$10)) -> 0 | G46: =IF(E46="FN","Fraude no detectado",IF(E46="FP","Alerta innecesaria",""))
A47: T031 | B47: 0.0001 | C47: 0 | D47: =--(B47>=$B$13) -> 0 | E47: =IF(C47=1,IF(D47=1,"TP","FN"),IF(D47=1,"FP","TN")) -> TN | F47: =IF(C47=1,IF(D47=1,$B$6,$B$9),IF(D47=1,$B$7,$B$10)) -> 0 | G47: =IF(E47="FN","Fraude no detectado",IF(E47="FP","Alerta innecesaria",""))
A48: T032 | B48: 0.000462 | C48: 0 | D48: =--(B48>=$B$13) -> 0 | E48: =IF(C48=1,IF(D48=1,"TP","FN"),IF(D48=1,"FP","TN")) -> TN | F48: =IF(C48=1,IF(D48=1,$B$6,$B$9),IF(D48=1,$B$7,$B$10)) -> 0 | G48: =IF(E48="FN","Fraude no detectado",IF(E48="FP","Alerta innecesaria",""))
A49: T033 | B49: 0.006696 | C49: 0 | D49: =--(B49>=$B$13) -> 0 | E49: =IF(C49=1,IF(D49=1,"TP","FN"),IF(D49=1,"FP","TN")) -> TN | F49: =IF(C49=1,IF(D49=1,$B$6,$B$9),IF(D49=1,$B$7,$B$10)) -> 0 | G49: =IF(E49="FN","Fraude no detectado",IF(E49="FP","Alerta innecesaria","")) | J49: Umbral | K49: Costo total ($)
A50: T034 | B50: 0.000106 | C50: 0 | D50: =--(B50>=$B$13) -> 0 | E50: =IF(C50=1,IF(D50=1,"TP","FN"),IF(D50=1,"FP","TN")) -> TN | F50: =IF(C50=1,IF(D50=1,$B$6,$B$9),IF(D50=1,$B$7,$B$10)) -> 0 | G50: =IF(E50="FN","Fraude no detectado",IF(E50="FP","Alerta innecesaria","")) | J50: =TEXT(J5,"0.0%") -> 0.0% | K50: =K5 -> 500
A51: T035 | B51: 0.001135 | C51: 0 | D51: =--(B51>=$B$13) -> 0 | E51: =IF(C51=1,IF(D51=1,"TP","FN"),IF(D51=1,"FP","TN")) -> TN | F51: =IF(C51=1,IF(D51=1,$B$6,$B$9),IF(D51=1,$B$7,$B$10)) -> 0 | G51: =IF(E51="FN","Fraude no detectado",IF(E51="FP","Alerta innecesaria","")) | J51: =TEXT(J9,"0.0%") -> 2.0% | K51: =K9 -> 520
A52: T036 | B52: 0.012305 | C52: 0 | D52: =--(B52>=$B$13) -> 1 | E52: =IF(C52=1,IF(D52=1,"TP","FN"),IF(D52=1,"FP","TN")) -> FP | F52: =IF(C52=1,IF(D52=1,$B$6,$B$9),IF(D52=1,$B$7,$B$10)) -> 5 | G52: =IF(E52="FN","Fraude no detectado",IF(E52="FP","Alerta innecesaria","")) -> Alerta innecesaria | J52: =TEXT(J13,"0.0%") -> 4.0% | K52: =K13 -> 505
A53: T037 | B53: 0.000153 | C53: 0 | D53: =--(B53>=$B$13) -> 0 | E53: =IF(C53=1,IF(D53=1,"TP","FN"),IF(D53=1,"FP","TN")) -> TN | F53: =IF(C53=1,IF(D53=1,$B$6,$B$9),IF(D53=1,$B$7,$B$10)) -> 0 | G53: =IF(E53="FN","Fraude no detectado",IF(E53="FP","Alerta innecesaria","")) | J53: =TEXT(J17,"0.0%") -> 6.0% | K53: =K17 -> 505
A54: T038 | B54: 0.002567 | C54: 0 | D54: =--(B54>=$B$13) -> 0 | E54: =IF(C54=1,IF(D54=1,"TP","FN"),IF(D54=1,"FP","TN")) -> TN | F54: =IF(C54=1,IF(D54=1,$B$6,$B$9),IF(D54=1,$B$7,$B$10)) -> 0 | G54: =IF(E54="FN","Fraude no detectado",IF(E54="FP","Alerta innecesaria","")) | J54: =TEXT(J21,"0.0%") -> 8.0% | K54: =K21 -> 500
A55: T039 | B55: 0.0001 | C55: 0 | D55: =--(B55>=$B$13) -> 0 | E55: =IF(C55=1,IF(D55=1,"TP","FN"),IF(D55=1,"FP","TN")) -> TN | F55: =IF(C55=1,IF(D55=1,$B$6,$B$9),IF(D55=1,$B$7,$B$10)) -> 0 | G55: =IF(E55="FN","Fraude no detectado",IF(E55="FP","Alerta innecesaria","")) | J55: =TEXT(J25,"0.0%") -> 10.0% | K55: =K25 -> 500
A56: T040 | B56: 0.000332 | C56: 0 | D56: =--(B56>=$B$13) -> 0 | E56: =IF(C56=1,IF(D56=1,"TP","FN"),IF(D56=1,"FP","TN")) -> TN | F56: =IF(C56=1,IF(D56=1,$B$6,$B$9),IF(D56=1,$B$7,$B$10)) -> 0 | G56: =IF(E56="FN","Fraude no detectado",IF(E56="FP","Alerta innecesaria","")) | J56: =TEXT(J29,"0.0%") -> 12.0% | K56: =K29 -> 500
A57: T041 | B57: 0.005269 | C57: 0 | D57: =--(B57>=$B$13) -> 0 | E57: =IF(C57=1,IF(D57=1,"TP","FN"),IF(D57=1,"FP","TN")) -> TN | F57: =IF(C57=1,IF(D57=1,$B$6,$B$9),IF(D57=1,$B$7,$B$10)) -> 0 | G57: =IF(E57="FN","Fraude no detectado",IF(E57="FP","Alerta innecesaria","")) | J57: =TEXT(J33,"0.0%") -> 14.0% | K57: =K33 -> 500
...

Sheet 3_Costo_por_monto
A1: Decisión costo-sensible por transacción: umbral individual según monto
A2: Matriz de Bahnsen: CTPᵢ = Ca, CFPᵢ = Ca, CFNᵢ = montoᵢ × tasa de pérdida, CTNᵢ = 0. El monto modifica la regla de decisión y genera un umbral económico distinto para cada operación.
A4: Supuestos editables | E4: Comparación económica | T4: Umbral global | U4: Costo total ($) | V4: TP | W4: FP | X4: FN | Y4: TN
A5: Costo administrativo Ca ($) | B5: 5 | C5: Costo de investigar/contactar, sea TP o FP | E5: Costo sin modelo (todo legítimo) | F5: =SUMIF($D$17:$D$116,1,$G$17:$G$116)+SUMIF($D$17:$D$116,0,$H$17:$H$116) -> 1500 | T5: 0 | U5: =SUMPRODUCT(--($C$17:$C$116>=T5),--($D$17:$D$116=1),$E$17:$E$116)+SUMPRODUCT(--($C$17:$C$116>=T5),--($D$17:$D$116=0),$F$17:$F$116)+SUMPRODUCT(--($C$17:$C$116<T5),--($D$17:$D$116=1),$G$17:$G$116)+SUMPRODUCT(--($C$17:$C$116<T5),--($D$17:$D$116=0),$H$17:$H$116) -> 500 | V5: =COUNTIFS($C$17:$C$116,">="&T5,$D$17:$D$116,1) -> 1 | W5: =COUNTIFS($C$17:$C$116,">="&T5,$D$17:$D$116,0) -> 99 | X5: =COUNTIFS($C$17:$C$116,"<"&T5,$D$17:$D$116,1) -> 0 | Y5: =COUNTIFS($C$17:$C$116,"<"&T5,$D$17:$D$116,0) -> 0
A6: Tasa de pérdida si el fraude pasa | B6: 1 | C6: 100% del monto; se puede bajar por recuperos | E6: Costo con umbral 50% | F6: =SUM($O$17:$O$116) -> 1500 | T6: =T5+$B$11 -> 0.005 | U6: =SUMPRODUCT(--($C$17:$C$116>=T6),--($D$17:$D$116=1),$E$17:$E$116)+SUMPRODUCT(--($C$17:$C$116>=T6),--($D$17:$D$116=0),$F$17:$F$116)+SUMPRODUCT(--($C$17:$C$116<T6),--($D$17:$D$116=1),$G$17:$G$116)+SUMPRODUCT(--($C$17:$C$116<T6),--($D$17:$D$116=0),$H$17:$H$116) -> 130 | V6: =COUNTIFS($C$17:$C$116,">="&T6,$D$17:$D$116,1) -> 1 | W6: =COUNTIFS($C$17:$C$116,">="&T6,$D$17:$D$116,0) -> 25 | X6: =COUNTIFS($C$17:$C$116,"<"&T6,$D$17:$D$116,1) -> 0 | Y6: =COUNTIFS($C$17:$C$116,"<"&T6,$D$17:$D$116,0) -> 74
A7: Costo verdadero negativo CTN ($) | B7: 0 | C7: Sin costo | E7: Costo con mejor umbral global | F7: =SUM($Q$17:$Q$116) -> 70 | T7: =T6+$B$11 -> 0.01 | U7: =SUMPRODUCT(--($C$17:$C$116>=T7),--($D$17:$D$116=1),$E$17:$E$116)+SUMPRODUCT(--($C$17:$C$116>=T7),--($D$17:$D$116=0),$F$17:$F$116)+SUMPRODUCT(--($C$17:$C$116<T7),--($D$17:$D$116=1),$G$17:$G$116)+SUMPRODUCT(--($C$17:$C$116<T7),--($D$17:$D$116=0),$H$17:$H$116) -> 70 | V7: =COUNTIFS($C$17:$C$116,">="&T7,$D$17:$D$116,1) -> 1 | W7: =COUNTIFS($C$17:$C$116,">="&T7,$D$17:$D$116,0) -> 13 | X7: =COUNTIFS($C$17:$C$116,"<"&T7,$D$17:$D$116,1) -> 0 | Y7: =COUNTIFS($C$17:$C$116,"<"&T7,$D$17:$D$116,0) -> 86
A8: Umbral convencional | B8: 0.5 | C8: Referencia, no necesariamente óptimo | E8: Costo con Bayes individual | F8: =SUM($M$17:$M$116) -> 20 | T8: =T7+$B$11 -> 0.015 | U8: =SUMPRODUCT(--($C$17:$C$116>=T8),--($D$17:$D$116=1),$E$17:$E$116)+SUMPRODUCT(--($C$17:$C$116>=T8),--($D$17:$D$116=0),$F$17:$F$116)+SUMPRODUCT(--($C$17:$C$116<T8),--($D$17:$D$116=1),$G$17:$G$116)+SUMPRODUCT(--($C$17:$C$116<T8),--($D$17:$D$116=0),$H$17:$H$116) -> 1530 | V8: =COUNTIFS($C$17:$C$116,">="&T8,$D$17:$D$116,1) -> 0 | W8: =COUNTIFS($C$17:$C$116,">="&T8,$D$17:$D$116,0) -> 6 | X8: =COUNTIFS($C$17:$C$116,"<"&T8,$D$17:$D$116,1) -> 1 | Y8: =COUNTIFS($C$17:$C$116,"<"&T8,$D$17:$D$116,0) -> 93
A9: Tasa de fraude observada | B9: =COUNTIF($D$17:$D$116,1)/COUNT($D$17:$D$116) -> 0.01 | C9: Fraudes reales / total de transacciones | E9: Ahorro Bayes vs. sin modelo | F9: =IFERROR(1-F8/F5,0) -> 0.98666667 | T9: =T8+$B$11 -> 0.02 | U9: =SUMPRODUCT(--($C$17:$C$116>=T9),--($D$17:$D$116=1),$E$17:$E$116)+SUMPRODUCT(--($C$17:$C$116>=T9),--($D$17:$D$116=0),$F$17:$F$116)+SUMPRODUCT(--($C$17:$C$116<T9),--($D$17:$D$116=1),$G$17:$G$116)+SUMPRODUCT(--($C$17:$C$116<T9),--($D$17:$D$116=0),$H$17:$H$116) -> 1520 | V9: =COUNTIFS($C$17:$C$116,">="&T9,$D$17:$D$116,1) -> 0 | W9: =COUNTIFS($C$17:$C$116,">="&T9,$D$17:$D$116,0) -> 4 | X9: =COUNTIFS($C$17:$C$116,"<"&T9,$D$17:$D$116,1) -> 1 | Y9: =COUNTIFS($C$17:$C$116,"<"&T9,$D$17:$D$116,0) -> 95
A10: Mejor umbral global | B10: =INDEX($T$5:$T$105,MATCH(MIN($U$5:$U$105),$U$5:$U$105,0)) -> 0.01 | C10: Minimiza costo total con un único corte | E10: Ahorro global vs. sin modelo | F10: =IFERROR(1-F7/F5,0) -> 0.95333333 | T10: =T9+$B$11 -> 0.025 | U10: =SUMPRODUCT(--($C$17:$C$116>=T10),--($D$17:$D$116=1),$E$17:$E$116)+SUMPRODUCT(--($C$17:$C$116>=T10),--($D$17:$D$116=0),$F$17:$F$116)+SUMPRODUCT(--($C$17:$C$116<T10),--($D$17:$D$116=1),$G$17:$G$116)+SUMPRODUCT(--($C$17:$C$116<T10),--($D$17:$D$116=0),$H$17:$H$116) -> 1515 | V10: =COUNTIFS($C$17:$C$116,">="&T10,$D$17:$D$116,1) -> 0 | W10: =COUNTIFS($C$17:$C$116,">="&T10,$D$17:$D$116,0) -> 3 | X10: =COUNTIFS($C$17:$C$116,"<"&T10,$D$17:$D$116,1) -> 1 | Y10: =COUNTIFS($C$17:$C$116,"<"&T10,$D$17:$D$116,0) -> 96
A11: Paso de la grilla | B11: 0.005 | C11: 0,5 puntos porcentuales | E11: Alertas Bayes individual | F11: =SUM($L$17:$L$116) -> 4 | T11: =T10+$B$11 -> 0.03 | U11: =SUMPRODUCT(--($C$17:$C$116>=T11),--($D$17:$D$116=1),$E$17:$E$116)+SUMPRODUCT(--($C$17:$C$116>=T11),--($D$17:$D$116=0),$F$17:$F$116)+SUMPRODUCT(--($C$17:$C$116<T11),--($D$17:$D$116=1),$G$17:$G$116)+SUMPRODUCT(--($C$17:$C$116<T11),--($D$17:$D$116=0),$H$17:$H$116) -> 1510 | V11: =COUNTIFS($C$17:$C$116,">="&T11,$D$17:$D$116,1) -> 0 | W11: =COUNTIFS($C$17:$C$116,">="&T11,$D$17:$D$116,0) -> 2 | X11: =COUNTIFS($C$17:$C$116,"<"&T11,$D$17:$D$116,1) -> 1 | Y11: =COUNTIFS($C$17:$C$116,"<"&T11,$D$17:$D$116,0) -> 97
A12: Regla individual simplificada | B12: = Ca / (monto × tasa de pérdida) | C12: Con CTP=CFP=Ca y CTN=0: umbralᵢ = Ca/CFNᵢ | E12: Alertas mejor global | F12: =SUM($P$17:$P$116) -> 14 | T12: =T11+$B$11 -> 0.035 | U12: =SUMPRODUCT(--($C$17:$C$116>=T12),--($D$17:$D$116=1),$E$17:$E$116)+SUMPRODUCT(--($C$17:$C$116>=T12),--($D$17:$D$116=0),$F$17:$F$116)+SUMPRODUCT(--($C$17:$C$116<T12),--($D$17:$D$116=1),$G$17:$G$116)+SUMPRODUCT(--($C$17:$C$116<T12),--($D$17:$D$116=0),$H$17:$H$116) -> 1510 | V12: =COUNTIFS($C$17:$C$116,">="&T12,$D$17:$D$116,1) -> 0 | W12: =COUNTIFS($C$17:$C$116,">="&T12,$D$17:$D$116,0) -> 2 | X12: =COUNTIFS($C$17:$C$116,"<"&T12,$D$17:$D$116,1) -> 1 | Y12: =COUNTIFS($C$17:$C$116,"<"&T12,$D$17:$D$116,0) -> 97
E13: Recall Bayes individual | F13: =IFERROR(COUNTIFS($L$17:$L$116,1,$D$17:$D$116,1)/COUNTIF($D$17:$D$116,1),0) -> 1 | T13: =T12+$B$11 -> 0.04 | U13: =SUMPRODUCT(--($C$17:$C$116>=T13),--($D$17:$D$116=1),$E$17:$E$116)+SUMPRODUCT(--($C$17:$C$116>=T13),--($D$17:$D$116=0),$F$17:$F$116)+SUMPRODUCT(--($C$17:$C$116<T13),--($D$17:$D$116=1),$G$17:$G$116)+SUMPRODUCT(--($C$17:$C$116<T13),--($D$17:$D$116=0),$H$17:$H$116) -> 1505 | V13: =COUNTIFS($C$17:$C$116,">="&T13,$D$17:$D$116,1) -> 0 | W13: =COUNTIFS($C$17:$C$116,">="&T13,$D$17:$D$116,0) -> 1 | X13: =COUNTIFS($C$17:$C$116,"<"&T13,$D$17:$D$116,1) -> 1 | Y13: =COUNTIFS($C$17:$C$116,"<"&T13,$D$17:$D$116,0) -> 98
E14: Recall mejor global | F14: =IFERROR(COUNTIFS($P$17:$P$116,1,$D$17:$D$116,1)/COUNTIF($D$17:$D$116,1),0) -> 1 | T14: =T13+$B$11 -> 0.045 | U14: =SUMPRODUCT(--($C$17:$C$116>=T14),--($D$17:$D$116=1),$E$17:$E$116)+SUMPRODUCT(--($C$17:$C$116>=T14),--($D$17:$D$116=0),$F$17:$F$116)+SUMPRODUCT(--($C$17:$C$116<T14),--($D$17:$D$116=1),$G$17:$G$116)+SUMPRODUCT(--($C$17:$C$116<T14),--($D$17:$D$116=0),$H$17:$H$116) -> 1505 | V14: =COUNTIFS($C$17:$C$116,">="&T14,$D$17:$D$116,1) -> 0 | W14: =COUNTIFS($C$17:$C$116,">="&T14,$D$17:$D$116,0) -> 1 | X14: =COUNTIFS($C$17:$C$116,"<"&T14,$D$17:$D$116,1) -> 1 | Y14: =COUNTIFS($C$17:$C$116,"<"&T14,$D$17:$D$116,0) -> 98
T15: =T14+$B$11 -> 0.05 | U15: =SUMPRODUCT(--($C$17:$C$116>=T15),--($D$17:$D$116=1),$E$17:$E$116)+SUMPRODUCT(--($C$17:$C$116>=T15),--($D$17:$D$116=0),$F$17:$F$116)+SUMPRODUCT(--($C$17:$C$116<T15),--($D$17:$D$116=1),$G$17:$G$116)+SUMPRODUCT(--($C$17:$C$116<T15),--($D$17:$D$116=0),$H$17:$H$116) -> 1505 | V15: =COUNTIFS($C$17:$C$116,">="&T15,$D$17:$D$116,1) -> 0 | W15: =COUNTIFS($C$17:$C$116,">="&T15,$D$17:$D$116,0) -> 1 | X15: =COUNTIFS($C$17:$C$116,"<"&T15,$D$17:$D$116,1) -> 1 | Y15: =COUNTIFS($C$17:$C$116,"<"&T15,$D$17:$D$116,0) -> 98
A16: ID | B16: Monto ($) | C16: Prob. fraude estimada | D16: Fraude real | E16: CTPᵢ ($) | F16: CFPᵢ ($) | G16: CFNᵢ ($) | H16: CTNᵢ ($) | I16: Riesgo si alerta | J16: Riesgo si deja pasar | K16: Umbral individual | L16: Decisión Bayes | M16: Costo Bayes ($) | N16: Pred. 50% | O16: Costo 50% ($) | P16: Pred. umbral global | Q16: Costo global ($) | R16: Resultado Bayes | T16: =T15+$B$11 -> 0.055 | U16: =SUMPRODUCT(--($C$17:$C$116>=T16),--($D$17:$D$116=1),$E$17:$E$116)+SUMPRODUCT(--($C$17:$C$116>=T16),--($D$17:$D$116=0),$F$17:$F$116)+SUMPRODUCT(--($C$17:$C$116<T16),--($D$17:$D$116=1),$G$17:$G$116)+SUMPRODUCT(--($C$17:$C$116<T16),--($D$17:$D$116=0),$H$17:$H$116) -> 1505 | V16: =COUNTIFS($C$17:$C$116,">="&T16,$D$17:$D$116,1) -> 0 | W16: =COUNTIFS($C$17:$C$116,">="&T16,$D$17:$D$116,0) -> 1 | X16: =COUNTIFS($C$17:$C$116,"<"&T16,$D$17:$D$116,1) -> 1 | Y16: =COUNTIFS($C$17:$C$116,"<"&T16,$D$17:$D$116,0) -> 98
A17: ='2_Costos_fijos'!A17 -> T001 | B17: 115.05 | C17: ='2_Costos_fijos'!B17 -> 0.0001 | D17: ='2_Costos_fijos'!C17 -> 0 | E17: =$B$5 -> 5 | F17: =$B$5 -> 5 | G17: =B17*$B$6 -> 115.05 | H17: =$B$7 -> 0 | I17: =C17*E17+(1-C17)*F17 -> 5 | J17: =C17*G17+(1-C17)*H17 -> 0.011505 | K17: =IF((F17-H17)+(G17-E17)<=0,1,MIN(1,MAX(0,(F17-H17)/((F17-H17)+(G17-E17))))) -> 0.043459365 | L17: =--(I17<=J17) -> 0 | M17: =IF(D17=1,IF(L17=1,E17,G17),IF(L17=1,F17,H17)) -> 0 | N17: =--(C17>=$B$8) -> 0 | O17: =IF(D17=1,IF(N17=1,E17,G17),IF(N17=1,F17,H17)) -> 0 | P17: =--(C17>=$B$10) -> 0 | Q17: =IF(D17=1,IF(P17=1,E17,G17),IF(P17=1,F17,H17)) -> 0 | R17: =IF(D17=1,IF(L17=1,"TP","FN"),IF(L17=1,"FP","TN")) -> TN | T17: =T16+$B$11 -> 0.06 | U17: =SUMPRODUCT(--($C$17:$C$116>=T17),--($D$17:$D$116=1),$E$17:$E$116)+SUMPRODUCT(--($C$17:$C$116>=T17),--($D$17:$D$116=0),$F$17:$F$116)+SUMPRODUCT(--($C$17:$C$116<T17),--($D$17:$D$116=1),$G$17:$G$116)+SUMPRODUCT(--($C$17:$C$116<T17),--($D$17:$D$116=0),$H$17:$H$116) -> 1505 | V17: =COUNTIFS($C$17:$C$116,">="&T17,$D$17:$D$116,1) -> 0 | W17: =COUNTIFS($C$17:$C$116,">="&T17,$D$17:$D$116,0) -> 1 | X17: =COUNTIFS($C$17:$C$116,"<"&T17,$D$17:$D$116,1) -> 1 | Y17: =COUNTIFS($C$17:$C$116,"<"&T17,$D$17:$D$116,0) -> 98
A18: ='2_Costos_fijos'!A18 -> T002 | B18: 54.77 | C18: ='2_Costos_fijos'!B18 -> 0.000209 | D18: ='2_Costos_fijos'!C18 -> 0 | E18: =$B$5 -> 5 | F18: =$B$5 -> 5 | G18: =B18*$B$6 -> 54.77 | H18: =$B$7 -> 0 | I18: =C18*E18+(1-C18)*F18 -> 5 | J18: =C18*G18+(1-C18)*H18 -> 0.01144693 | K18: =IF((F18-H18)+(G18-E18)<=0,1,MIN(1,MAX(0,(F18-H18)/((F18-H18)+(G18-E18))))) -> 0.091290853 | L18: =--(I18<=J18) -> 0 | M18: =IF(D18=1,IF(L18=1,E18,G18),IF(L18=1,F18,H18)) -> 0 | N18: =--(C18>=$B$8) -> 0 | O18: =IF(D18=1,IF(N18=1,E18,G18),IF(N18=1,F18,H18)) -> 0 | P18: =--(C18>=$B$10) -> 0 | Q18: =IF(D18=1,IF(P18=1,E18,G18),IF(P18=1,F18,H18)) -> 0 | R18: =IF(D18=1,IF(L18=1,"TP","FN"),IF(L18=1,"FP","TN")) -> TN | T18: =T17+$B$11 -> 0.065 | U18: =SUMPRODUCT(--($C$17:$C$116>=T18),--($D$17:$D$116=1),$E$17:$E$116)+SUMPRODUCT(--($C$17:$C$116>=T18),--($D$17:$D$116=0),$F$17:$F$116)+SUMPRODUCT(--($C$17:$C$116<T18),--($D$17:$D$116=1),$G$17:$G$116)+SUMPRODUCT(--($C$17:$C$116<T18),--($D$17:$D$116=0),$H$17:$H$116) -> 1500 | V18: =COUNTIFS($C$17:$C$116,">="&T18,$D$17:$D$116,1) -> 0 | W18: =COUNTIFS($C$17:$C$116,">="&T18,$D$17:$D$116,0) -> 0 | X18: =COUNTIFS($C$17:$C$116,"<"&T18,$D$17:$D$116,1) -> 1 | Y18: =COUNTIFS($C$17:$C$116,"<"&T18,$D$17:$D$116,0) -> 99
A19: ='2_Costos_fijos'!A19 -> T003 | B19: 315.7 | C19: ='2_Costos_fijos'!B19 -> 0.0036 | D19: ='2_Costos_fijos'!C19 -> 0 | E19: =$B$5 -> 5 | F19: =$B$5 -> 5 | G19: =B19*$B$6 -> 315.7 | H19: =$B$7 -> 0 | I19: =C19*E19+(1-C19)*F19 -> 5 | J19: =C19*G19+(1-C19)*H19 -> 1.13652 | K19: =IF((F19-H19)+(G19-E19)<=0,1,MIN(1,MAX(0,(F19-H19)/((F19-H19)+(G19-E19))))) -> 0.015837821 | L19: =--(I19<=J19) -> 0 | M19: =IF(D19=1,IF(L19=1,E19,G19),IF(L19=1,F19,H19)) -> 0 | N19: =--(C19>=$B$8) -> 0 | O19: =IF(D19=1,IF(N19=1,E19,G19),IF(N19=1,F19,H19)) -> 0 | P19: =--(C19>=$B$10) -> 0 | Q19: =IF(D19=1,IF(P19=1,E19,G19),IF(P19=1,F19,H19)) -> 0 | R19: =IF(D19=1,IF(L19=1,"TP","FN"),IF(L19=1,"FP","TN")) -> TN | T19: =T18+$B$11 -> 0.07 | U19: =SUMPRODUCT(--($C$17:$C$116>=T19),--($D$17:$D$116=1),$E$17:$E$116)+SUMPRODUCT(--($C$17:$C$116>=T19),--($D$17:$D$116=0),$F$17:$F$116)+SUMPRODUCT(--($C$17:$C$116<T19),--($D$17:$D$116=1),$G$17:$G$116)+SUMPRODUCT(--($C$17:$C$116<T19),--($D$17:$D$116=0),$H$17:$H$116) -> 1500 | V19: =COUNTIFS($C$17:$C$116,">="&T19,$D$17:$D$116,1) -> 0 | W19: =COUNTIFS($C$17:$C$116,">="&T19,$D$17:$D$116,0) -> 0 | X19: =COUNTIFS($C$17:$C$116,"<"&T19,$D$17:$D$116,1) -> 1 | Y19: =COUNTIFS($C$17:$C$116,"<"&T19,$D$17:$D$116,0) -> 99
A20: ='2_Costos_fijos'!A20 -> T004 | B20: 78.41 | C20: ='2_Costos_fijos'!B20 -> 0.0001 | D20: ='2_Costos_fijos'!C20 -> 0 | E20: =$B$5 -> 5 | F20: =$B$5 -> 5 | G20: =B20*$B$6 -> 78.41 | H20: =$B$7 -> 0 | I20: =C20*E20+(1-C20)*F20 -> 5 | J20: =C20*G20+(1-C20)*H20 -> 0.007841 | K20: =IF((F20-H20)+(G20-E20)<=0,1,MIN(1,MAX(0,(F20-H20)/((F20-H20)+(G20-E20))))) -> 0.063767377 | L20: =--(I20<=J20) -> 0 | M20: =IF(D20=1,IF(L20=1,E20,G20),IF(L20=1,F20,H20)) -> 0 | N20: =--(C20>=$B$8) -> 0 | O20: =IF(D20=1,IF(N20=1,E20,G20),IF(N20=1,F20,H20)) -> 0 | P20: =--(C20>=$B$10) -> 0 | Q20: =IF(D20=1,IF(P20=1,E20,G20),IF(P20=1,F20,H20)) -> 0 | R20: =IF(D20=1,IF(L20=1,"TP","FN"),IF(L20=1,"FP","TN")) -> TN | T20: =T19+$B$11 -> 0.075 | U20: =SUMPRODUCT(--($C$17:$C$116>=T20),--($D$17:$D$116=1),$E$17:$E$116)+SUMPRODUCT(--($C$17:$C$116>=T20),--($D$17:$D$116=0),$F$17:$F$116)+SUMPRODUCT(--($C$17:$C$116<T20),--($D$17:$D$116=1),$G$17:$G$116)+SUMPRODUCT(--($C$17:$C$116<T20),--($D$17:$D$116=0),$H$17:$H$116) -> 1500 | V20: =COUNTIFS($C$17:$C$116,">="&T20,$D$17:$D$116,1) -> 0 | W20: =COUNTIFS($C$17:$C$116,">="&T20,$D$17:$D$116,0) -> 0 | X20: =COUNTIFS($C$17:$C$116,"<"&T20,$D$17:$D$116,1) -> 1 | Y20: =COUNTIFS($C$17:$C$116,"<"&T20,$D$17:$D$116,0) -> 99
A21: ='2_Costos_fijos'!A21 -> T005 | B21: 33.93 | C21: ='2_Costos_fijos'!B21 -> 0.000502 | D21: ='2_Costos_fijos'!C21 -> 0 | E21: =$B$5 -> 5 | F21: =$B$5 -> 5 | G21: =B21*$B$6 -> 33.93 | H21: =$B$7 -> 0 | I21: =C21*E21+(1-C21)*F21 -> 5 | J21: =C21*G21+(1-C21)*H21 -> 0.01703286 | K21: =IF((F21-H21)+(G21-E21)<=0,1,MIN(1,MAX(0,(F21-H21)/((F21-H21)+(G21-E21))))) -> 0.14736222 | L21: =--(I21<=J21) -> 0 | M21: =IF(D21=1,IF(L21=1,E21,G21),IF(L21=1,F21,H21)) -> 0 | N21: =--(C21>=$B$8) -> 0 | O21: =IF(D21=1,IF(N21=1,E21,G21),IF(N21=1,F21,H21)) -> 0 | P21: =--(C21>=$B$10) -> 0 | Q21: =IF(D21=1,IF(P21=1,E21,G21),IF(P21=1,F21,H21)) -> 0 | R21: =IF(D21=1,IF(L21=1,"TP","FN"),IF(L21=1,"FP","TN")) -> TN | T21: =T20+$B$11 -> 0.08 | U21: =SUMPRODUCT(--($C$17:$C$116>=T21),--($D$17:$D$116=1),$E$17:$E$116)+SUMPRODUCT(--($C$17:$C$116>=T21),--($D$17:$D$116=0),$F$17:$F$116)+SUMPRODUCT(--($C$17:$C$116<T21),--($D$17:$D$116=1),$G$17:$G$116)+SUMPRODUCT(--($C$17:$C$116<T21),--($D$17:$D$116=0),$H$17:$H$116) -> 1500 | V21: =COUNTIFS($C$17:$C$116,">="&T21,$D$17:$D$116,1) -> 0 | W21: =COUNTIFS($C$17:$C$116,">="&T21,$D$17:$D$116,0) -> 0 | X21: =COUNTIFS($C$17:$C$116,"<"&T21,$D$17:$D$116,1) -> 1 | Y21: =COUNTIFS($C$17:$C$116,"<"&T21,$D$17:$D$116,0) -> 99
A22: ='2_Costos_fijos'!A22 -> T006 | B22: 158.39 | C22: ='2_Costos_fijos'!B22 -> 0.007099 | D22: ='2_Costos_fijos'!C22 -> 0 | E22: =$B$5 -> 5 | F22: =$B$5 -> 5 | G22: =B22*$B$6 -> 158.39 | H22: =$B$7 -> 0 | I22: =C22*E22+(1-C22)*F22 -> 5 | J22: =C22*G22+(1-C22)*H22 -> 1.1244106 | K22: =IF((F22-H22)+(G22-E22)<=0,1,MIN(1,MAX(0,(F22-H22)/((F22-H22)+(G22-E22))))) -> 0.031567649 | L22: =--(I22<=J22) -> 0 | M22: =IF(D22=1,IF(L22=1,E22,G22),IF(L22=1,F22,H22)) -> 0 | N22: =--(C22>=$B$8) -> 0 | O22: =IF(D22=1,IF(N22=1,E22,G22),IF(N22=1,F22,H22)) -> 0 | P22: =--(C22>=$B$10) -> 0 | Q22: =IF(D22=1,IF(P22=1,E22,G22),IF(P22=1,F22,H22)) -> 0 | R22: =IF(D22=1,IF(L22=1,"TP","FN"),IF(L22=1,"FP","TN")) -> TN | T22: =T21+$B$11 -> 0.085 | U22: =SUMPRODUCT(--($C$17:$C$116>=T22),--($D$17:$D$116=1),$E$17:$E$116)+SUMPRODUCT(--($C$17:$C$116>=T22),--($D$17:$D$116=0),$F$17:$F$116)+SUMPRODUCT(--($C$17:$C$116<T22),--($D$17:$D$116=1),$G$17:$G$116)+SUMPRODUCT(--($C$17:$C$116<T22),--($D$17:$D$116=0),$H$17:$H$116) -> 1500 | V22: =COUNTIFS($C$17:$C$116,">="&T22,$D$17:$D$116,1) -> 0 | W22: =COUNTIFS($C$17:$C$116,">="&T22,$D$17:$D$116,0) -> 0 | X22: =COUNTIFS($C$17:$C$116,"<"&T22,$D$17:$D$116,1) -> 1 | Y22: =COUNTIFS($C$17:$C$116,"<"&T22,$D$17:$D$116,0) -> 99
A23: ='2_Costos_fijos'!A23 -> T007 | B23: 28 | C23: ='2_Costos_fijos'!B23 -> 0.000108 | D23: ='2_Costos_fijos'!C23 -> 0 | E23: =$B$5 -> 5 | F23: =$B$5 -> 5 | G23: =B23*$B$6 -> 28 | H23: =$B$7 -> 0 | I23: =C23*E23+(1-C23)*F23 -> 5 | J23: =C23*G23+(1-C23)*H23 -> 0.003024 | K23: =IF((F23-H23)+(G23-E23)<=0,1,MIN(1,MAX(0,(F23-H23)/((F23-H23)+(G23-E23))))) -> 0.17857143 | L23: =--(I23<=J23) -> 0 | M23: =IF(D23=1,IF(L23=1,E23,G23),IF(L23=1,F23,H23)) -> 0 | N23: =--(C23>=$B$8) -> 0 | O23: =IF(D23=1,IF(N23=1,E23,G23),IF(N23=1,F23,H23)) -> 0 | P23: =--(C23>=$B$10) -> 0 | Q23: =IF(D23=1,IF(P23=1,E23,G23),IF(P23=1,F23,H23)) -> 0 | R23: =IF(D23=1,IF(L23=1,"TP","FN"),IF(L23=1,"FP","TN")) -> TN | T23: =T22+$B$11 -> 0.09 | U23: =SUMPRODUCT(--($C$17:$C$116>=T23),--($D$17:$D$116=1),$E$17:$E$116)+SUMPRODUCT(--($C$17:$C$116>=T23),--($D$17:$D$116=0),$F$17:$F$116)+SUMPRODUCT(--($C$17:$C$116<T23),--($D$17:$D$116=1),$G$17:$G$116)+SUMPRODUCT(--($C$17:$C$116<T23),--($D$17:$D$116=0),$H$17:$H$116) -> 1500 | V23: =COUNTIFS($C$17:$C$116,">="&T23,$D$17:$D$116,1) -> 0 | W23: =COUNTIFS($C$17:$C$116,">="&T23,$D$17:$D$116,0) -> 0 | X23: =COUNTIFS($C$17:$C$116,"<"&T23,$D$17:$D$116,1) -> 1 | Y23: =COUNTIFS($C$17:$C$116,"<"&T23,$D$17:$D$116,0) -> 99
A24: ='2_Costos_fijos'!A24 -> T008 | B24: 511.85 | C24: ='2_Costos_fijos'!B24 -> 0.02 | D24: ='2_Costos_fijos'!C24 -> 0 | E24: =$B$5 -> 5 | F24: =$B$5 -> 5 | G24: =B24*$B$6 -> 511.85 | H24: =$B$7 -> 0 | I24: =C24*E24+(1-C24)*F24 -> 5 | J24: =C24*G24+(1-C24)*H24 -> 10.237 | K24: =IF((F24-H24)+(G24-E24)<=0,1,MIN(1,MAX(0,(F24-H24)/((F24-H24)+(G24-E24))))) -> 0.0097684869 | L24: =--(I24<=J24) -> 1 | M24: =IF(D24=1,IF(L24=1,E24,G24),IF(L24=1,F24,H24)) -> 5 | N24: =--(C24>=$B$8) -> 0 | O24: =IF(D24=1,IF(N24=1,E24,G24),IF(N24=1,F24,H24)) -> 0 | P24: =--(C24>=$B$10) -> 1 | Q24: =IF(D24=1,IF(P24=1,E24,G24),IF(P24=1,F24,H24)) -> 5 | R24: =IF(D24=1,IF(L24=1,"TP","FN"),IF(L24=1,"FP","TN")) -> FP | T24: =T23+$B$11 -> 0.095 | U24: =SUMPRODUCT(--($C$17:$C$116>=T24),--($D$17:$D$116=1),$E$17:$E$116)+SUMPRODUCT(--($C$17:$C$116>=T24),--($D$17:$D$116=0),$F$17:$F$116)+SUMPRODUCT(--($C$17:$C$116<T24),--($D$17:$D$116=1),$G$17:$G$116)+SUMPRODUCT(--($C$17:$C$116<T24),--($D$17:$D$116=0),$H$17:$H$116) -> 1500 | V24: =COUNTIFS($C$17:$C$116,">="&T24,$D$17:$D$116,1) -> 0 | W24: =COUNTIFS($C$17:$C$116,">="&T24,$D$17:$D$116,0) -> 0 | X24: =COUNTIFS($C$17:$C$116,"<"&T24,$D$17:$D$116,1) -> 1 | Y24: =COUNTIFS($C$17:$C$116,"<"&T24,$D$17:$D$116,0) -> 99
A25: ='2_Costos_fijos'!A25 -> T009 | B25: 65.07 | C25: ='2_Costos_fijos'!B25 -> 0.012961 | D25: ='2_Costos_fijos'!C25 -> 0 | E25: =$B$5 -> 5 | F25: =$B$5 -> 5 | G25: =B25*$B$6 -> 65.07 | H25: =$B$7 -> 0 | I25: =C25*E25+(1-C25)*F25 -> 5 | J25: =C25*G25+(1-C25)*H25 -> 0.84337227 | K25: =IF((F25-H25)+(G25-E25)<=0,1,MIN(1,MAX(0,(F25-H25)/((F25-H25)+(G25-E25))))) -> 0.076840326 | L25: =--(I25<=J25) -> 0 | M25: =IF(D25=1,IF(L25=1,E25,G25),IF(L25=1,F25,H25)) -> 0 | N25: =--(C25>=$B$8) -> 0 | O25: =IF(D25=1,IF(N25=1,E25,G25),IF(N25=1,F25,H25)) -> 0 | P25: =--(C25>=$B$10) -> 1 | Q25: =IF(D25=1,IF(P25=1,E25,G25),IF(P25=1,F25,H25)) -> 5 | R25: =IF(D25=1,IF(L25=1,"TP","FN"),IF(L25=1,"FP","TN")) -> TN | T25: =T24+$B$11 -> 0.1 | U25: =SUMPRODUCT(--($C$17:$C$116>=T25),--($D$17:$D$116=1),$E$17:$E$116)+SUMPRODUCT(--($C$17:$C$116>=T25),--($D$17:$D$116=0),$F$17:$F$116)+SUMPRODUCT(--($C$17:$C$116<T25),--($D$17:$D$116=1),$G$17:$G$116)+SUMPRODUCT(--($C$17:$C$116<T25),--($D$17:$D$116=0),$H$17:$H$116) -> 1500 | V25: =COUNTIFS($C$17:$C$116,">="&T25,$D$17:$D$116,1) -> 0 | W25: =COUNTIFS($C$17:$C$116,">="&T25,$D$17:$D$116,0) -> 0 | X25: =COUNTIFS($C$17:$C$116,"<"&T25,$D$17:$D$116,1) -> 1 | Y25: =COUNTIFS($C$17:$C$116,"<"&T25,$D$17:$D$116,0) -> 99
A26: ='2_Costos_fijos'!A26 -> T010 | B26: 293.63 | C26: ='2_Costos_fijos'!B26 -> 0.000162 | D26: ='2_Costos_fijos'!C26 -> 0 | E26: =$B$5 -> 5 | F26: =$B$5 -> 5 | G26: =B26*$B$6 -> 293.63 | H26: =$B$7 -> 0 | I26: =C26*E26+(1-C26)*F26 -> 5 | J26: =C26*G26+(1-C26)*H26 -> 0.04756806 | K26: =IF((F26-H26)+(G26-E26)<=0,1,MIN(1,MAX(0,(F26-H26)/((F26-H26)+(G26-E26))))) -> 0.017028233 | L26: =--(I26<=J26) -> 0 | M26: =IF(D26=1,IF(L26=1,E26,G26),IF(L26=1,F26,H26)) -> 0 | N26: =--(C26>=$B$8) -> 0 | O26: =IF(D26=1,IF(N26=1,E26,G26),IF(N26=1,F26,H26)) -> 0 | P26: =--(C26>=$B$10) -> 0 | Q26: =IF(D26=1,IF(P26=1,E26,G26),IF(P26=1,F26,H26)) -> 0 | R26: =IF(D26=1,IF(L26=1,"TP","FN"),IF(L26=1,"FP","TN")) -> TN | T26: =T25+$B$11 -> 0.105 | U26: =SUMPRODUCT(--($C$17:$C$116>=T26),--($D$17:$D$116=1),$E$17:$E$116)+SUMPRODUCT(--($C$17:$C$116>=T26),--($D$17:$D$116=0),$F$17:$F$116)+SUMPRODUCT(--($C$17:$C$116<T26),--($D$17:$D$116=1),$G$17:$G$116)+SUMPRODUCT(--($C$17:$C$116<T26),--($D$17:$D$116=0),$H$17:$H$116) -> 1500 | V26: =COUNTIFS($C$17:$C$116,">="&T26,$D$17:$D$116,1) -> 0 | W26: =COUNTIFS($C$17:$C$116,">="&T26,$D$17:$D$116,0) -> 0 | X26: =COUNTIFS($C$17:$C$116,"<"&T26,$D$17:$D$116,1) -> 1 | Y26: =COUNTIFS($C$17:$C$116,"<"&T26,$D$17:$D$116,0) -> 99
A27: ='2_Costos_fijos'!A27 -> T011 | B27: 405.19 | C27: ='2_Costos_fijos'!B27 -> 0.002751 | D27: ='2_Costos_fijos'!C27 -> 0 | E27: =$B$5 -> 5 | F27: =$B$5 -> 5 | G27: =B27*$B$6 -> 405.19 | H27: =$B$7 -> 0 | I27: =C27*E27+(1-C27)*F27 -> 5 | J27: =C27*G27+(1-C27)*H27 -> 1.1146777 | K27: =IF((F27-H27)+(G27-E27)<=0,1,MIN(1,MAX(0,(F27-H27)/((F27-H27)+(G27-E27))))) -> 0.01233989 | L27: =--(I27<=J27) -> 0 | M27: =IF(D27=1,IF(L27=1,E27,G27),IF(L27=1,F27,H27)) -> 0 | N27: =--(C27>=$B$8) -> 0 | O27: =IF(D27=1,IF(N27=1,E27,G27),IF(N27=1,F27,H27)) -> 0 | P27: =--(C27>=$B$10) -> 0 | Q27: =IF(D27=1,IF(P27=1,E27,G27),IF(P27=1,F27,H27)) -> 0 | R27: =IF(D27=1,IF(L27=1,"TP","FN"),IF(L27=1,"FP","TN")) -> TN | T27: =T26+$B$11 -> 0.11 | U27: =SUMPRODUCT(--($C$17:$C$116>=T27),--($D$17:$D$116=1),$E$17:$E$116)+SUMPRODUCT(--($C$17:$C$116>=T27),--($D$17:$D$116=0),$F$17:$F$116)+SUMPRODUCT(--($C$17:$C$116<T27),--($D$17:$D$116=1),$G$17:$G$116)+SUMPRODUCT(--($C$17:$C$116<T27),--($D$17:$D$116=0),$H$17:$H$116) -> 1500 | V27: =COUNTIFS($C$17:$C$116,">="&T27,$D$17:$D$116,1) -> 0 | W27: =COUNTIFS($C$17:$C$116,">="&T27,$D$17:$D$116,0) -> 0 | X27: =COUNTIFS($C$17:$C$116,"<"&T27,$D$17:$D$116,1) -> 1 | Y27: =COUNTIFS($C$17:$C$116,"<"&T27,$D$17:$D$116,0) -> 99
A28: ='2_Costos_fijos'!A28 -> T012 | B28: 632.38 | C28: ='2_Costos_fijos'!B28 -> 0.0001 | D28: ='2_Costos_fijos'!C28 -> 0 | E28: =$B$5 -> 5 | F28: =$B$5 -> 5 | G28: =B28*$B$6 -> 632.38 | H28: =$B$7 -> 0 | I28: =C28*E28+(1-C28)*F28 -> 5 | J28: =C28*G28+(1-C28)*H28 -> 0.063238 | K28: =IF((F28-H28)+(G28-E28)<=0,1,MIN(1,MAX(0,(F28-H28)/((F28-H28)+(G28-E28))))) -> 0.0079066384 | L28: =--(I28<=J28) -> 0 | M28: =IF(D28=1,IF(L28=1,E28,G28),IF(L28=1,F28,H28)) -> 0 | N28: =--(C28>=$B$8) -> 0 | O28: =IF(D28=1,IF(N28=1,E28,G28),IF(N28=1,F28,H28)) -> 0 | P28: =--(C28>=$B$10) -> 0 | Q28: =IF(D28=1,IF(P28=1,E28,G28),IF(P28=1,F28,H28)) -> 0 | R28: =IF(D28=1,IF(L28=1,"TP","FN"),IF(L28=1,"FP","TN")) -> TN | T28: =T27+$B$11 -> 0.115 | U28: =SUMPRODUCT(--($C$17:$C$116>=T28),--($D$17:$D$116=1),$E$17:$E$116)+SUMPRODUCT(--($C$17:$C$116>=T28),--($D$17:$D$116=0),$F$17:$F$116)+SUMPRODUCT(--($C$17:$C$116<T28),--($D$17:$D$116=1),$G$17:$G$116)+SUMPRODUCT(--($C$17:$C$116<T28),--($D$17:$D$116=0),$H$17:$H$116) -> 1500 | V28: =COUNTIFS($C$17:$C$116,">="&T28,$D$17:$D$116,1) -> 0 | W28: =COUNTIFS($C$17:$C$116,">="&T28,$D$17:$D$116,0) -> 0 | X28: =COUNTIFS($C$17:$C$116,"<"&T28,$D$17:$D$116,1) -> 1 | Y28: =COUNTIFS($C$17:$C$116,"<"&T28,$D$17:$D$116,0) -> 99
... A105: ='2_Costos_fijos'!A105 -> T089 | B105: 64.53 | C105: ='2_Costos_fijos'!B105 -> 0.000969 | D105: ='2_Costos_fijos'!C105 -> 0 | E105: =$B$5 -> 5 | F105: =$B$5 -> 5 | G105: =B105*$B$6 -> 64.53 | H105: =$B$7 -> 0 | I105: =C105*E105+(1-C105)*F105 -> 5 | J105: =C105*G105+(1-C105)*H105 -> 0.06252957 | K105: =IF((F105-H105)+(G105-E105)<=0,1,MIN(1,MAX(0,(F105-H105)/((F105-H105)+(G105-E105))))) -> 0.077483341 | L105: =--(I105<=J105) -> 0 | M105: =IF(D105=1,IF(L105=1,E105,G105),IF(L105=1,F105,H105)) -> 0 | N105: =--(C105>=$B$8) -> 0 | O105: =IF(D105=1,IF(N105=1,E105,G105),IF(N105=1,F105,H105)) -> 0 | P105: =--(C105>=$B$10) -> 0 | Q105: =IF(D105=1,IF(P105=1,E105,G105),IF(P105=1,F105,H105)) -> 0 | R105: =IF(D105=1,IF(L105=1,"TP","FN"),IF(L105=1,"FP","TN")) -> TN | T105: =T104+$B$11 -> 0.5 | U105: =SUMPRODUCT(--($C$17:$C$116>=T105),--($D$17:$D$116=1),$E$17:$E$116)+SUMPRODUCT(--($C$17:$C$116>=T105),--($D$17:$D$116=0),$F$17:$F$116)+SUMPRODUCT(--($C$17:$C$116<T105),--($D$17:$D$116=1),$G$17:$G$116)+SUMPRODUCT(--($C$17:$C$116<T105),--($D$17:$D$116=0),$H$17:$H$116) -> 1500 | V105: =COUNTIFS($C$17:$C$116,">="&T105,$D$17:$D$116,1) -> 0 | W105: =COUNTIFS($C$17:$C$116,">="&T105,$D$17:$D$116,0) -> 0 | X105: =COUNTIFS($C$17:$C$116,"<"&T105,$D$17:$D$116,1) -> 1 | Y105: =COUNTIFS($C$17:$C$116,"<"&T105,$D$17:$D$116,0) -> 99
A106: ='2_Costos_fijos'!A106 -> T090 | B106: 163.79 | C106: ='2_Costos_fijos'!B106 -> 0.011073 | D106: ='2_Costos_fijos'!C106 -> 0 | E106: =$B$5 -> 5 | F106: =$B$5 -> 5 | G106: =B106*$B$6 -> 163.79 | H106: =$B$7 -> 0 | I106: =C106*E106+(1-C106)*F106 -> 5 | J106: =C106*G106+(1-C106)*H106 -> 1.8136467 | K106: =IF((F106-H106)+(G106-E106)<=0,1,MIN(1,MAX(0,(F106-H106)/((F106-H106)+(G106-E106))))) -> 0.030526894 | L106: =--(I106<=J106) -> 0 | M106: =IF(D106=1,IF(L106=1,E106,G106),IF(L106=1,F106,H106)) -> 0 | N106: =--(C106>=$B$8) -> 0 | O106: =IF(D106=1,IF(N106=1,E106,G106),IF(N106=1,F106,H106)) -> 0 | P106: =--(C106>=$B$10) -> 1 | Q106: =IF(D106=1,IF(P106=1,E106,G106),IF(P106=1,F106,H106)) -> 5 | R106: =IF(D106=1,IF(L106=1,"TP","FN"),IF(L106=1,"FP","TN")) -> TN
A107: ='2_Costos_fijos'!A107 -> T091 | B107: 15.06 | C107: ='2_Costos_fijos'!B107 -> 0.025 | D107: ='2_Costos_fijos'!C107 -> 0 | E107: =$B$5 -> 5 | F107: =$B$5 -> 5 | G107: =B107*$B$6 -> 15.06 | H107: =$B$7 -> 0 | I107: =C107*E107+(1-C107)*F107 -> 5 | J107: =C107*G107+(1-C107)*H107 -> 0.3765 | K107: =IF((F107-H107)+(G107-E107)<=0,1,MIN(1,MAX(0,(F107-H107)/((F107-H107)+(G107-E107))))) -> 0.33200531 | L107: =--(I107<=J107) -> 0 | M107: =IF(D107=1,IF(L107=1,E107,G107),IF(L107=1,F107,H107)) -> 0 | N107: =--(C107>=$B$8) -> 0 | O107: =IF(D107=1,IF(N107=1,E107,G107),IF(N107=1,F107,H107)) -> 0 | P107: =--(C107>=$B$10) -> 1 | Q107: =IF(D107=1,IF(P107=1,E107,G107),IF(P107=1,F107,H107)) -> 5 | R107: =IF(D107=1,IF(L107=1,"TP","FN"),IF(L107=1,"FP","TN")) -> TN
A108: ='2_Costos_fijos'!A108 -> T092 | B108: 42.87 | C108: ='2_Costos_fijos'!B108 -> 0.00223 | D108: ='2_Costos_fijos'!C108 -> 0 | E108: =$B$5 -> 5 | F108: =$B$5 -> 5 | G108: =B108*$B$6 -> 42.87 | H108: =$B$7 -> 0 | I108: =C108*E108+(1-C108)*F108 -> 5 | J108: =C108*G108+(1-C108)*H108 -> 0.0956001 | K108: =IF((F108-H108)+(G108-E108)<=0,1,MIN(1,MAX(0,(F108-H108)/((F108-H108)+(G108-E108))))) -> 0.11663168 | L108: =--(I108<=J108) -> 0 | M108: =IF(D108=1,IF(L108=1,E108,G108),IF(L108=1,F108,H108)) -> 0 | N108: =--(C108>=$B$8) -> 0 | O108: =IF(D108=1,IF(N108=1,E108,G108),IF(N108=1,F108,H108)) -> 0 | P108: =--(C108>=$B$10) -> 0 | Q108: =IF(D108=1,IF(P108=1,E108,G108),IF(P108=1,F108,H108)) -> 0 | R108: =IF(D108=1,IF(L108=1,"TP","FN"),IF(L108=1,"FP","TN")) -> TN | T108: Umbral | U108: Costo total ($)
A109: ='2_Costos_fijos'!A109 -> T093 | B109: 137.11 | C109: ='2_Costos_fijos'!B109 -> 0.0001 | D109: ='2_Costos_fijos'!C109 -> 0 | E109: =$B$5 -> 5 | F109: =$B$5 -> 5 | G109: =B109*$B$6 -> 137.11 | H109: =$B$7 -> 0 | I109: =C109*E109+(1-C109)*F109 -> 5 | J109: =C109*G109+(1-C109)*H109 -> 0.013711 | K109: =IF((F109-H109)+(G109-E109)<=0,1,MIN(1,MAX(0,(F109-H109)/((F109-H109)+(G109-E109))))) -> 0.03646707 | L109: =--(I109<=J109) -> 0 | M109: =IF(D109=1,IF(L109=1,E109,G109),IF(L109=1,F109,H109)) -> 0 | N109: =--(C109>=$B$8) -> 0 | O109: =IF(D109=1,IF(N109=1,E109,G109),IF(N109=1,F109,H109)) -> 0 | P109: =--(C109>=$B$10) -> 0 | Q109: =IF(D109=1,IF(P109=1,E109,G109),IF(P109=1,F109,H109)) -> 0 | R109: =IF(D109=1,IF(L109=1,"TP","FN"),IF(L109=1,"FP","TN")) -> TN | T109: =TEXT(T5,"0%") -> 0% | U109: =U5 -> 500
A110: ='2_Costos_fijos'!A110 -> T094 | B110: 25.26 | C110: ='2_Costos_fijos'!B110 -> 0.000283 | D110: ='2_Costos_fijos'!C110 -> 0 | E110: =$B$5 -> 5 | F110: =$B$5 -> 5 | G110: =B110*$B$6 -> 25.26 | H110: =$B$7 -> 0 | I110: =C110*E110+(1-C110)*F110 -> 5 | J110: =C110*G110+(1-C110)*H110 -> 0.00714858 | K110: =IF((F110-H110)+(G110-E110)<=0,1,MIN(1,MAX(0,(F110-H110)/((F110-H110)+(G110-E110))))) -> 0.19794141 | L110: =--(I110<=J110) -> 0 | M110: =IF(D110=1,IF(L110=1,E110,G110),IF(L110=1,F110,H110)) -> 0 | N110: =--(C110>=$B$8) -> 0 | O110: =IF(D110=1,IF(N110=1,E110,G110),IF(N110=1,F110,H110)) -> 0 | P110: =--(C110>=$B$10) -> 0 | Q110: =IF(D110=1,IF(P110=1,E110,G110),IF(P110=1,F110,H110)) -> 0 | R110: =IF(D110=1,IF(L110=1,"TP","FN"),IF(L110=1,"FP","TN")) -> TN | T110: =TEXT(T15,"0%") -> 5% | U110: =U15 -> 1505
A111: ='2_Costos_fijos'!A111 -> T095 | B111: 23.25 | C111: ='2_Costos_fijos'!B111 -> 0.004654 | D111: ='2_Costos_fijos'!C111 -> 0 | E111: =$B$5 -> 5 | F111: =$B$5 -> 5 | G111: =B111*$B$6 -> 23.25 | H111: =$B$7 -> 0 | I111: =C111*E111+(1-C111)*F111 -> 5 | J111: =C111*G111+(1-C111)*H111 -> 0.1082055 | K111: =IF((F111-H111)+(G111-E111)<=0,1,MIN(1,MAX(0,(F111-H111)/((F111-H111)+(G111-E111))))) -> 0.21505376 | L111: =--(I111<=J111) -> 0 | M111: =IF(D111=1,IF(L111=1,E111,G111),IF(L111=1,F111,H111)) -> 0 | N111: =--(C111>=$B$8) -> 0 | O111: =IF(D111=1,IF(N111=1,E111,G111),IF(N111=1,F111,H111)) -> 0 | P111: =--(C111>=$B$10) -> 0 | Q111: =IF(D111=1,IF(P111=1,E111,G111),IF(P111=1,F111,H111)) -> 0 | R111: =IF(D111=1,IF(L111=1,"TP","FN"),IF(L111=1,"FP","TN")) -> TN | T111: =TEXT(T25,"0%") -> 10% | U111: =U25 -> 1500
A112: ='2_Costos_fijos'!A112 -> T096 | B112: 35.5 | C112: ='2_Costos_fijos'!B112 -> 0.000101 | D112: ='2_Costos_fijos'!C112 -> 0 | E112: =$B$5 -> 5 | F112: =$B$5 -> 5 | G112: =B112*$B$6 -> 35.5 | H112: =$B$7 -> 0 | I112: =C112*E112+(1-C112)*F112 -> 5 | J112: =C112*G112+(1-C112)*H112 -> 0.0035855 | K112: =IF((F112-H112)+(G112-E112)<=0,1,MIN(1,MAX(0,(F112-H112)/((F112-H112)+(G112-E112))))) -> 0.14084507 | L112: =--(I112<=J112) -> 0 | M112: =IF(D112=1,IF(L112=1,E112,G112),IF(L112=1,F112,H112)) -> 0 | N112: =--(C112>=$B$8) -> 0 | O112: =IF(D112=1,IF(N112=1,E112,G112),IF(N112=1,F112,H112)) -> 0 | P112: =--(C112>=$B$10) -> 0 | Q112: =IF(D112=1,IF(P112=1,E112,G112),IF(P112=1,F112,H112)) -> 0 | R112: =IF(D112=1,IF(L112=1,"TP","FN"),IF(L112=1,"FP","TN")) -> TN | T112: =TEXT(T35,"0%") -> 15% | U112: =U35 -> 1500
A113: ='2_Costos_fijos'!A113 -> T097 | B113: 69.01 | C113: ='2_Costos_fijos'!B113 -> 0.0007 | D113: ='2_Costos_fijos'!C113 -> 0 | E113: =$B$5 -> 5 | F113: =$B$5 -> 5 | G113: =B113*$B$6 -> 69.01 | H113: =$B$7 -> 0 | I113: =C113*E113+(1-C113)*F113 -> 5 | J113: =C113*G113+(1-C113)*H113 -> 0.048307 | K113: =IF((F113-H113)+(G113-E113)<=0,1,MIN(1,MAX(0,(F113-H113)/((F113-H113)+(G113-E113))))) -> 0.072453268 | L113: =--(I113<=J113) -> 0 | M113: =IF(D113=1,IF(L113=1,E113,G113),IF(L113=1,F113,H113)) -> 0 | N113: =--(C113>=$B$8) -> 0 | O113: =IF(D113=1,IF(N113=1,E113,G113),IF(N113=1,F113,H113)) -> 0 | P113: =--(C113>=$B$10) -> 0 | Q113: =IF(D113=1,IF(P113=1,E113,G113),IF(P113=1,F113,H113)) -> 0 | R113: =IF(D113=1,IF(L113=1,"TP","FN"),IF(L113=1,"FP","TN")) -> TN | T113: =TEXT(T45,"0%") -> 20% | U113: =U45 -> 1500
A114: ='2_Costos_fijos'!A114 -> T098 | B114: 620.97 | C114: ='2_Costos_fijos'!B114 -> 0.008908 | D114: ='2_Costos_fijos'!C114 -> 0 | E114: =$B$5 -> 5 | F114: =$B$5 -> 5 | G114: =B114*$B$6 -> 620.97 | H114: =$B$7 -> 0 | I114: =C114*E114+(1-C114)*F114 -> 5 | J114: =C114*G114+(1-C114)*H114 -> 5.5316008 | K114: =IF((F114-H114)+(G114-E114)<=0,1,MIN(1,MAX(0,(F114-H114)/((F114-H114)+(G114-E114))))) -> 0.0080519188 | L114: =--(I114<=J114) -> 1 | M114: =IF(D114=1,IF(L114=1,E114,G114),IF(L114=1,F114,H114)) -> 5 | N114: =--(C114>=$B$8) -> 0 | O114: =IF(D114=1,IF(N114=1,E114,G114),IF(N114=1,F114,H114)) -> 0 | P114: =--(C114>=$B$10) -> 0 | Q114: =IF(D114=1,IF(P114=1,E114,G114),IF(P114=1,F114,H114)) -> 0 | R114: =IF(D114=1,IF(L114=1,"TP","FN"),IF(L114=1,"FP","TN")) -> FP | T114: =TEXT(T55,"0%") -> 25% | U114: =U55 -> 1500
A115: ='2_Costos_fijos'!A115 -> T099 | B115: 195.67 | C115: ='2_Costos_fijos'!B115 -> 0.000119 | D115: ='2_Costos_fijos'!C115 -> 0 | E115: =$B$5 -> 5 | F115: =$B$5 -> 5 | G115: =B115*$B$6 -> 195.67 | H115: =$B$7 -> 0 | I115: =C115*E115+(1-C115)*F115 -> 5 | J115: =C115*G115+(1-C115)*H115 -> 0.02328473 | K115: =IF((F115-H115)+(G115-E115)<=0,1,MIN(1,MAX(0,(F115-H115)/((F115-H115)+(G115-E115))))) -> 0.025553227 | L115: =--(I115<=J115) -> 0 | M115: =IF(D115=1,IF(L115=1,E115,G115),IF(L115=1,F115,H115)) -> 0 | N115: =--(C115>=$B$8) -> 0 | O115: =IF(D115=1,IF(N115=1,E115,G115),IF(N115=1,F115,H115)) -> 0 | P115: =--(C115>=$B$10) -> 0 | Q115: =IF(D115=1,IF(P115=1,E115,G115),IF(P115=1,F115,H115)) -> 0 | R115: =IF(D115=1,IF(L115=1,"TP","FN"),IF(L115=1,"FP","TN")) -> TN | T115: =TEXT(T65,"0%") -> 30% | U115: =U65 -> 1500
A116: ='2_Costos_fijos'!A116 -> T100 | B116: 19.91 | C116: ='2_Costos_fijos'!B116 -> 0.001665 | D116: ='2_Costos_fijos'!C116 -> 0 | E116: =$B$5 -> 5 | F116: =$B$5 -> 5 | G116: =B116*$B$6 -> 19.91 | H116: =$B$7 -> 0 | I116: =C116*E116+(1-C116)*F116 -> 5 | J116: =C116*G116+(1-C116)*H116 -> 0.03315015 | K116: =IF((F116-H116)+(G116-E116)<=0,1,MIN(1,MAX(0,(F116-H116)/((F116-H116)+(G116-E116))))) -> 0.25113009 | L116: =--(I116<=J116) -> 0 | M116: =IF(D116=1,IF(L116=1,E116,G116),IF(L116=1,F116,H116)) -> 0 | N116: =--(C116>=$B$8) -> 0 | O116: =IF(D116=1,IF(N116=1,E116,G116),IF(N116=1,F116,H116)) -> 0 | P116: =--(C116>=$B$10) -> 0 | Q116: =IF(D116=1,IF(P116=1,E116,G116),IF(P116=1,F116,H116)) -> 0 | R116: =IF(D116=1,IF(L116=1,"TP","FN"),IF(L116=1,"FP","TN")) -> TN | T116: =TEXT(T75,"0%") -> 35% | U116: =U75 -> 1500
T117: =TEXT(T85,"0%") -> 40% | U117: =U85 -> 1500
...

Sheet 4_Guia_y_fuentes
A1: Guía de uso, fundamentos y fuentes
A3: Secuencia sugerida
A4: 1 | B4: En la hoja 1, comenzar con umbral 50% y observar FN, costo y ahorro.
A5: 2 | B5: Cambiar el umbral usado por el umbral teórico y luego por el empírico.
A6: 3 | B6: Modificar el multiplicador del falso negativo y observar cómo cae o sube el umbral.
A7: 4 | B7: Explicar por qué el mejor umbral debe elegirse en validación, no en test.
A8: 5 | B8: Pasar a la hoja 2 y comparar 50%, mejor umbral global y Bayes individual.
A9: 6 | B9: Cambiar monto, costo administrativo o tasa de pérdida y observar el umbral individual.
A10: 7 | B10: Cerrar comparando el umbral global con la regla individual dependiente del monto.
A12: Fórmulas clave
A13: Riesgo de alertar | B13: p·CTP + (1-p)·CFP
A14: Riesgo de dejar pasar | B14: p·CFN + (1-p)·CTN
A15: Decisión Bayes | B15: Alertar cuando Riesgo(alertar) ≤ Riesgo(dejar pasar)
A16: Umbral general | B16: (CFP-CTN) / [(CFP-CTN) + (CFN-CTP)]
A17: Matriz por monto | B17: CTPᵢ=Ca; CFPᵢ=Ca; CFNᵢ=montoᵢ×tasa de pérdida; CTNᵢ=0
A18: Umbral simplificado | B18: Ca / (montoᵢ×tasa de pérdida)
A19: Savings | B19: 1 - costo del modelo / costo del clasificador ingenuo
A21: Fuentes
A22: Correa Bahnsen — presentación Fraud Analytics | B22: https://es.slideshare.net/slideshow/1510-fraud-analyticslong/57178459 | C22: Diapositivas 32–34: costos FP/FN y necesidad de costos dependientes del monto.
A23: CostCla — documentación | B23: https://albahnsen.github.io/CostSensitiveClassification/ | C23: Matriz de costos por observación, métricas de costo y savings.
A24: Bahnsen et al. — Bayes Minimum Risk | B24: https://albahnsen.github.io/files/Cost%20Sensitive%20Credit%20Card%20Fraud%20Detection%20using%20Bayes%20Minimum%20Risk%20-%20Publish.pdf | C24: Tablas II–III y ecuaciones de riesgo: Ca, 100·Ca y monto de la transacción.
A25: Nota sobre datos | B25: Datos construidos para enseñanza: 100 transacciones y 1 fraude (prevalencia de 1%). | C25: Los resultados numéricos son ilustrativos y no deben usarse como benchmark empírico.
A27: Advertencias metodológicas
A28: • Un umbral optimizado sobre test produce una evaluación optimista. Elegirlo en validación y congelarlo antes del test.
A29: • Si hubo undersampling/oversampling, la probabilidad cruda puede no reflejar la prevalencia real; recalibrar antes de BMR.
A30: • Los costos deben incluir recuperos, chargebacks, fricción del cliente, costo de revisión y capacidad operativa.
A31: • Si existe un límite de alertas diarias, la decisión pasa a ser una optimización con restricción, no sólo un umbral independiente.
A32: • Accuracy, recall y F1 son informativas, pero no sustituyen la función económica de pérdidas.

Sheet 5. Otro diseño
A42: El paquete costcla permite diseño 2 o 3
